Workbook

Sheet PRECIOS
F2: 45500
D3: PRECIOS ACUAC. DE AHOME
D4: PP | E4: +GR | F4: $ TOTAL
D5: 7 | E5: =+E6-1 -> 49 | F5: =+E5+D5 -> 56
D6: 8 | E6: =+E7-1 -> 50 | F6: =+E6+D6 -> 58
D7: 9 | E7: =+E8-1 -> 51 | F7: =+E7+D7 -> 60
D8: 10 | E8: 52 | F8: =+E8+D8 -> 62
D9: 11 | E9: =+E8+1 -> 53 | F9: =+E9+D9 -> 64
D10: 12 | E10: 55 | F10: =+E10+D10 -> 67
D11: 13 | E11: 55 | F11: =+E11+D11 -> 68
D12: 14 | E12: 60 | F12: =+E12+D12 -> 74
D13: 15 | E13: 65 | F13: =+E13+D13 -> 80
D14: 16 | E14: 60 | F14: =+E14+D14 -> 76
D15: 17 | E15: 62 | F15: =+E15+D15 -> 79
D16: 18 | E16: 62 | F16: =+E16+D16 -> 80
D17: 19 | E17: 62 | F17: =+E17+D17 -> 81
D18: 20 | E18: 64 | F18: =+E18+D18 -> 84
D19: 21 | E19: 64 | F19: =+E19+D19 -> 85
D20: 22 | E20: 64 | F20: =+E20+D20 -> 86
D21: 23 | E21: 64 | F21: =+E21+D21 -> 87
... D30: 34 | E30: 64 | F30: =+E30+D30 -> 98

Sheet INGRESO PERSONAL
F2: =240+92 -> 332 | BO2: RESUMEN NOMINA
E3: ENE | I3: MENS | J3: FEB. | N3: MENS | O3: MAR | S3: MENS | T3: APR | X3: MENS | Y3: MAY | AC3: MENS | AD3: JUN | AH3: MENS | AI3: JUL | AM3: MENS | AN3: AUG | AR3: MENS | AS3: SEP | AW3: MENS | AX3: OCT | BB3: MENS | BC3: NOV | BG3: MENS | BH3: DEC | BL3: MENS | BN3: PRESUPUESTO NOMINA DESEMBOCADEROS 2025 | CG3: =+'PROY GPO ESCOBEDO'!T3 -> 122.1 | CH3: HAS | CI3: GASTO
D4: PUESTO | E4: SEM1 | F4: SEM2 | G4: SEM3 | H4: SEM4 | I4: PERS | J4: SEM1 | K4: SEM2 | L4: SEM3 | M4: SEM4 | N4: PROM | O4: SEM1 | P4: SEM2 | Q4: SEM3 | R4: SEM4 | S4: PROM | T4: SEM1 | U4: SEM2 | V4: SEM3 | W4: SEM4 | X4: PROM | Y4: SEM1 | Z4: SEM2 | AA4: SEM3 | AB4: SEM4 | AC4: PROM | AD4: SEM1 | AE4: SEM2 | AF4: SEM3 | AG4: SEM4 | AH4: PROM | AI4: SEM1 | AJ4: SEM2 | AK4: SEM3 | AL4: SEM4 | AM4: PROM | AN4: SEM1 | AO4: SEM2 | AP4: SEM3 | AQ4: SEM4 | AR4: PROM | AS4: SEM1 | AT4: SEM2 | AU4: SEM3 | AV4: SEM4 | AW4: PROM | AX4: SEM1 | AY4: SEM2 | AZ4: SEM3 | BA4: SEM4 | BB4: PROM | BC4: SEM1 | BD4: SEM2 | BE4: SEM3 | BF4: SEM4 | BG4: PROM | BH4: SEM1 | BI4: SEM2 | BJ4: SEM3 | BK4: SEM4 | BL4: PROM | BN4: PUESTO | BO4: SEM. | BP4: MEN | BQ4: ANUAL | BR4: ENE | BS4: FEB. | BT4: MAR | BU4: ABR | BV4: MAY | BW4: JUN | BX4: JUL | BY4: AUG | BZ4: SEP | CA4: OCT | CB4: NOV | CC4: DEC | CD4: TOT | CF4: MES | CG4: NO PER | CH4: HAS/PER | CI4: MENSUAL | CJ4: COSTO/HA
D5: GERENTE DE GRANJA | AN5: 1 | AO5: 1 | AP5: 1 | AQ5: 1 | AR5: =AVERAGE(AN5:AQ5) -> 1 | AS5: 1 | AT5: 1 | AU5: 1 | AV5: 1 | AW5: =AVERAGE(AS5:AV5) -> 1 | AX5: 1 | AY5: 1 | AZ5: 1 | BA5: 1 | BB5: =AVERAGE(AX5:BA5) -> 1 | BC5: 1 | BD5: 1 | BE5: 1 | BF5: 1 | BG5: =AVERAGE(BC5:BF5) -> 1 | BH5: 1 | BI5: 1 | BJ5: 1 | BK5: 1 | BL5: =AVERAGE(BH5:BK5) -> 1 | BN5: GERENTE DE GRANJAS | BO5: 10000 | BP5: =+BO5/7*30 -> 42857.143 | BQ5: =+BP5*I5+N5*BP5+S5*BP5+X5*BP5+AC5*BP5+AH5*BP5+AM5*BP5+AR5*BP5+AW5*BP5+BB5*BP5+BG5*BP5+BL5*BP5 -> 214285.71 | BR5: =+I5*$BP5 -> 0 | BS5: =+N5*$BP5 -> 0 | BT5: =+S5*$BP5 -> 0 | BU5: =+X5*$BP5 -> 0 | BV5: =+AC5*$BP5 -> 0 | BW5: =+AH5*$BP5 -> 0 | BX5: =+AM5*$BP5 -> 0 | BY5: =+AR5*$BP5 -> 42857.143 | BZ5: =+AW5*$BP5 -> 42857.143 | CA5: =+BB5*$BP5 -> 42857.143 | CB5: =+BG5*$BP5 -> 42857.143 | CC5: =+BL5*$BP5 -> 42857.143 | CD5: =SUM(BR5:CC5) -> 214285.71 | CF5: ENER
D6: SUB GEREBTE PROD | AN6: 0 | AO6: 0 | AP6: 1 | AQ6: 1 | AR6: =AVERAGE(AN6:AQ6) -> 0.5 | AS6: 1 | AT6: 1 | AU6: 1 | AV6: 1 | AW6: =AVERAGE(AS6:AV6) -> 1 | AX6: 1 | AY6: 1 | AZ6: 1 | BA6: 1 | BB6: =AVERAGE(AX6:BA6) -> 1 | BC6: 1 | BD6: 1 | BE6: 1 | BF6: 1 | BG6: =AVERAGE(BC6:BF6) -> 1 | BH6: 1 | BI6: 1 | BJ6: 1 | BK6: 1 | BL6: =AVERAGE(BH6:BK6) -> 1 | BN6: SUB GEREBTE PROD | BO6: 4000 | BP6: 25714.286 | BQ6: =+BP6*I6+N6*BP6+S6*BP6+X6*BP6+AC6*BP6+AH6*BP6+AM6*BP6+AR6*BP6+AW6*BP6+BB6*BP6+BG6*BP6+BL6*BP6 -> 115714.29 | BR6: =+I6*$BP6 -> 0 | BS6: =+N6*$BP6 -> 0 | BT6: =+S6*$BP6 -> 0 | BU6: =+X6*$BP6 -> 0 | BV6: =+AC6*$BP6 -> 0 | BW6: =+AH6*$BP6 -> 0 | BX6: =+AM6*$BP6 -> 0 | BY6: =+AR6*$BP6 -> 12857.143 | BZ6: =+AW6*$BP6 -> 25714.286 | CA6: =+BB6*$BP6 -> 25714.286 | CB6: =+BG6*$BP6 -> 25714.286 | CC6: =+BL6*$BP6 -> 25714.286 | CD6: =SUM(BR6:CC6) -> 115714.29 | CF6: FEBRERO
D7: TECNICO EMPIRICO | AN7: 1 | AO7: 1 | AP7: 1 | AQ7: 2 | AR7: =AVERAGE(AN7:AQ7) -> 1.25 | AS7: 2 | AT7: 2 | AU7: 2 | AV7: 2 | AW7: =AVERAGE(AS7:AV7) -> 2 | AX7: 2 | AY7: 2 | AZ7: 2 | BA7: 2 | BB7: =AVERAGE(AX7:BA7) -> 2 | BC7: 2 | BD7: 2 | BE7: 2 | BF7: 1 | BG7: =AVERAGE(BC7:BF7) -> 1.75 | BH7: 1 | BI7: 1 | BJ7: 1 | BK7: 1 | BL7: =AVERAGE(BH7:BK7) -> 1 | BN7: TECNICO EMPIRICO | BO7: 3000 | BP7: =+BO7/7*30 -> 12857.143 | BQ7: =+BP7*I7+N7*BP7+S7*BP7+X7*BP7+AC7*BP7+AH7*BP7+AM7*BP7+AR7*BP7+AW7*BP7+BB7*BP7+BG7*BP7+BL7*BP7 -> 102857.14 | BR7: =+I7*$BP7 -> 0 | BS7: =+N7*$BP7 -> 0 | BT7: =+S7*$BP7 -> 0 | BU7: =+X7*$BP7 -> 0 | BV7: =+AC7*$BP7 -> 0 | BW7: =+AH7*$BP7 -> 0 | BX7: =+AM7*$BP7 -> 0 | BY7: =+AR7*$BP7 -> 16071.429 | BZ7: =+AW7*$BP7 -> 25714.286 | CA7: =+BB7*$BP7 -> 25714.286 | CB7: =+BG7*$BP7 -> 22500 | CC7: =+BL7*$BP7 -> 12857.143 | CD7: =SUM(BR7:CC7) -> 102857.14 | CF7: MARZO
D8: PARAMETRISTA | AN8: 1 | AO8: 1 | AP8: 1 | AQ8: 1 | AR8: =AVERAGE(AN8:AQ8) -> 1 | AS8: 1 | AT8: 1 | AU8: 1 | AV8: 1 | AW8: =AVERAGE(AS8:AV8) -> 1 | AX8: 1 | AY8: 1 | AZ8: 1 | BA8: 1 | BB8: =AVERAGE(AX8:BA8) -> 1 | BC8: 1 | BD8: 1 | BE8: 1 | BF8: 1 | BG8: =AVERAGE(BC8:BF8) -> 1 | BH8: 0 | BI8: 0 | BJ8: 0 | BK8: 0 | BL8: =AVERAGE(BH8:BK8) -> 0 | BN8: PARAMETRISTA | BO8: 2500 | BP8: =+BO8/7*30 -> 10714.286 | BQ8: =+BP8*I8+N8*BP8+S8*BP8+X8*BP8+AC8*BP8+AH8*BP8+AM8*BP8+AR8*BP8+AW8*BP8+BB8*BP8+BG8*BP8+BL8*BP8 -> 42857.143 | BR8: =+I8*$BP8 -> 0 | BS8: =+N8*$BP8 -> 0 | BT8: =+S8*$BP8 -> 0 | BU8: =+X8*$BP8 -> 0 | BV8: =+AC8*$BP8 -> 0 | BW8: =+AH8*$BP8 -> 0 | BX8: =+AM8*$BP8 -> 0 | BY8: =+AR8*$BP8 -> 10714.286 | BZ8: =+AW8*$BP8 -> 10714.286 | CA8: =+BB8*$BP8 -> 10714.286 | CB8: =+BG8*$BP8 -> 10714.286 | CC8: =+BL8*$BP8 -> 0 | CD8: =SUM(BR8:CC8) -> 42857.143 | CF8: ABRIL
D9: CHAROLERO | AN9: 0 | AO9: 0 | AP9: 0 | AQ9: 2 | AR9: =AVERAGE(AN9:AQ9) -> 0.5 | AS9: 2 | AT9: 2 | AU9: 2 | AV9: 2 | AW9: =AVERAGE(AS9:AV9) -> 2 | AX9: 2 | AY9: 2 | AZ9: 2 | BA9: 2 | BB9: =AVERAGE(AX9:BA9) -> 2 | BC9: 2 | BD9: 2 | BG9: =AVERAGE(BC9:BF9) -> 2 | BH9: 0 | BI9: 0 | BJ9: 0 | BK9: 0 | BL9: =AVERAGE(BH9:BK9) -> 0 | BN9: CHAROLERO | BO9: 2200 | BP9: =+BO9/7*30 -> 9428.5714 | BQ9: =+BP9*I9+N9*BP9+S9*BP9+X9*BP9+AC9*BP9+AH9*BP9+AM9*BP9+AR9*BP9+AW9*BP9+BB9*BP9+BG9*BP9+BL9*BP9 -> 61285.714 | BR9: =+I9*$BP9 -> 0 | BS9: =+N9*$BP9 -> 0 | BT9: =+S9*$BP9 -> 0 | BU9: =+X9*$BP9 -> 0 | BV9: =+AC9*$BP9 -> 0 | BW9: =+AH9*$BP9 -> 0 | BX9: =+AM9*$BP9 -> 0 | BY9: =+AR9*$BP9 -> 4714.2857 | BZ9: =+AW9*$BP9 -> 18857.143 | CA9: =+BB9*$BP9 -> 18857.143 | CB9: =+BG9*$BP9 -> 18857.143 | CC9: =+BL9*$BP9 -> 0 | CD9: =SUM(BR9:CC9) -> 61285.714 | CF9: MAYO
D10: TRACTORISTA | AN10: 1 | AO10: 1 | AP10: 1 | AQ10: 1 | AR10: =AVERAGE(AN10:AQ10) -> 1 | AS10: 1 | AT10: 1 | AU10: 1 | AV10: 1 | AW10: =AVERAGE(AS10:AV10) -> 1 | AX10: 1 | AY10: 1 | AZ10: 1 | BA10: 1 | BB10: =AVERAGE(AX10:BA10) -> 1 | BC10: 1 | BD10: 1 | BE10: 1 | BF10: 1 | BG10: =AVERAGE(BC10:BF10) -> 1 | BH10: 0 | BI10: 0 | BJ10: 0 | BK10: 0 | BL10: =AVERAGE(BH10:BK10) -> 0 | BN10: TRACTORISTA | BO10: 2500 | BP10: =+BO10/7*30 -> 10714.286 | BQ10: =+BP10*I10+N10*BP10+S10*BP10+X10*BP10+AC10*BP10+AH10*BP10+AM10*BP10+AR10*BP10+AW10*BP10+BB10*BP10+BG10*BP10+BL10*BP10 -> 42857.143 | BR10: =+I10*$BP10 -> 0 | BS10: =+N10*$BP10 -> 0 | BT10: =+S10*$BP10 -> 0 | BU10: =+X10*$BP10 -> 0 | BV10: =+AC10*$BP10 -> 0 | BW10: =+AH10*$BP10 -> 0 | BX10: =+AM10*$BP10 -> 0 | BY10: =+AR10*$BP10 -> 10714.286 | BZ10: =+AW10*$BP10 -> 10714.286 | CA10: =+BB10*$BP10 -> 10714.286 | CB10: =+BG10*$BP10 -> 10714.286 | CC10: =+BL10*$BP10 -> 0 | CD10: =SUM(BR10:CC10) -> 42857.143 | CF10: JUNIO | CK10: PRIMER CICLO
D11: ALIMENTADORES | AN11: 0 | AO11: 0 | AP11: 2 | AQ11: 2 | AR11: =AVERAGE(AN11:AQ11) -> 1 | AS11: 2 | AT11: 2 | AU11: 2 | AV11: 2 | AW11: =AVERAGE(AS11:AV11) -> 2 | AX11: 2 | AY11: 2 | AZ11: 2 | BA11: 2 | BB11: =AVERAGE(AX11:BA11) -> 2 | BC11: 2 | BD11: 2 | BE11: 2 | BF11: 2 | BG11: =AVERAGE(BC11:BF11) -> 2 | BH11: 0 | BI11: 0 | BJ11: 0 | BK11: 0 | BL11: =AVERAGE(BH11:BK11) -> 0 | BN11: ALIMENTADORES | BO11: 2200 | BP11: =+BO11/7*30 -> 9428.5714 | BQ11: =+BP11*I11+N11*BP11+S11*BP11+X11*BP11+AC11*BP11+AH11*BP11+AM11*BP11+AR11*BP11+AW11*BP11+BB11*BP11+BG11*BP11+BL11*BP11 -> 66000 | BT11: =+S11*$BP11 -> 0 | BU11: =+X11*$BP11 -> 0 | BV11: =+AC11*$BP11 -> 0 | BW11: =+AH11*$BP11 -> 0 | BX11: =+AM11*$BP11 -> 0 | BY11: =+AR11*$BP11 -> 9428.5714 | BZ11: =+AW11*$BP11 -> 18857.143 | CA11: =+BB11*$BP11 -> 18857.143 | CB11: =+BG11*$BP11 -> 18857.143 | CC11: =+BL11*$BP11 -> 0 | CD11: =SUM(BR11:CC11) -> 66000 | CF11: JULIO
D12: ACTIVIDADES DIVERSAS | AN12: 3 | AO12: 3 | AP12: 3 | AQ12: 3 | AR12: =AVERAGE(AN12:AQ12) -> 3 | AS12: 3 | AT12: 3 | AU12: 3 | AV12: 3 | AW12: =AVERAGE(AS12:AV12) -> 3 | AX12: 3 | AY12: 3 | AZ12: 3 | BA12: 3 | BB12: =AVERAGE(AX12:BA12) -> 3 | BC12: 3 | BD12: 3 | BE12: 4 | BF12: 2 | BG12: =AVERAGE(BC12:BF12) -> 3 | BH12: 2 | BI12: 2 | BJ12: 2 | BK12: 2 | BL12: =AVERAGE(BH12:BK12) -> 2 | BN12: ACTIVIDADES DIVERSAS | BO12: 2200 | BP12: =+BO12/7*30 -> 9428.5714 | BQ12: =+BP12*I12+N12*BP12+S12*BP12+X12*BP12+AC12*BP12+AH12*BP12+AM12*BP12+AR12*BP12+AW12*BP12+BB12*BP12+BG12*BP12+BL12*BP12 -> 132000 | BR12: =+I12*$BP12 -> 0 | BS12: =+N12*$BP12 -> 0 | BT12: =+S12*$BP12 -> 0 | BU12: =+X12*$BP12 -> 0 | BV12: =+AC12*$BP12 -> 0 | BW12: =+AH12*$BP12 -> 0 | BX12: =+AM12*$BP12 -> 0 | BY12: =+AR12*$BP12 -> 28285.714 | BZ12: =+AW12*$BP12 -> 28285.714 | CA12: =+BB12*$BP12 -> 28285.714 | CB12: =+BG12*$BP12 -> 28285.714 | CC12: =+BL12*$BP12 -> 18857.143 | CD12: =SUM(BR12:CC12) -> 132000 | CF12: AGOSTO | CG12: =AVERAGE(AN19:AQ19) -> 13.25 | CH12: =+CG$3/CG12 -> 9.2150943 | CI12: =+BY19 -> 178928.57 | CJ12: =+CI12/CG$3 -> 1465.4265
D13: COCINERA | AN13: 0 | AO13: 0 | AP13: 1 | AQ13: 1 | AR13: =AVERAGE(AN13:AQ13) -> 0.5 | AS13: 1 | AT13: 1 | AU13: 1 | AV13: 1 | AW13: =AVERAGE(AS13:AV13) -> 1 | AX13: 1 | AY13: 1 | AZ13: 1 | BA13: 1 | BB13: =AVERAGE(AX13:BA13) -> 1 | BC13: 1 | BD13: 1 | BE13: 1 | BF13: 0 | BG13: =AVERAGE(BC13:BF13) -> 0.75 | BH13: 0 | BI13: 0 | BJ13: 0 | BK13: 0 | BL13: =AVERAGE(BH13:BK13) -> 0 | BN13: COCINERA | BO13: 2000 | BP13: =+BO13/7*30 -> 8571.4286 | BQ13: =+BP13*I13+N13*BP13+S13*BP13+X13*BP13+AC13*BP13+AH13*BP13+AM13*BP13+AR13*BP13+AW13*BP13+BB13*BP13+BG13*BP13+BL13*BP13 -> 27857.143 | BR13: =+I13*$BP13 -> 0 | BS13: =+N13*$BP13 -> 0 | BT13: =+S13*$BP13 -> 0 | BU13: =+X13*$BP13 -> 0 | BV13: =+AC13*$BP13 -> 0 | BW13: =+AH13*$BP13 -> 0 | BX13: =+AM13*$BP13 -> 0 | BY13: =+AR13*$BP13 -> 4285.7143 | BZ13: =+AW13*$BP13 -> 8571.4286 | CA13: =+BB13*$BP13 -> 8571.4286 | CB13: =+BG13*$BP13 -> 6428.5714 | CC13: =+BL13*$BP13 -> 0 | CD13: =SUM(BR13:CC13) -> 27857.143 | CF13: SEPTIEMBRE | CG13: =AVERAGE(AS19:AV19) -> 18 | CH13: =+CG$3/CG13 -> 6.7833333 | CI13: =+BZ19 -> 210428.57 | CJ13: =+CI13/CG$3 -> 1723.4117
D14: JEFE DE BOMBEROS | AN14: 0 | AO14: 0 | AP14: 0 | AQ14: 0 | AR14: 1 | AS14: 0 | AT14: 0 | AU14: 0 | AV14: 0 | AW14: 1 | AX14: 0 | AY14: 0 | AZ14: 0 | BA14: 0 | BB14: 1 | BC14: 0 | BD14: 0 | BE14: 0 | BF14: 0 | BG14: 1 | BH14: 0 | BI14: 0 | BJ14: 0 | BK14: 0 | BL14: =AVERAGE(BH14:BK14) -> 0 | BN14: JEFE DE BOMBEROS | BO14: 0 | BP14: =+BO14/7*30 -> 0 | BQ14: =+BP14*I14+N14*BP14+S14*BP14+X14*BP14+AC14*BP14+AH14*BP14+AM14*BP14+AR14*BP14+AW14*BP14+BB14*BP14+BG14*BP14+BL14*BP14 -> 0 | BR14: =+I14*$BP14 -> 0 | BS14: =+N14*$BP14 -> 0 | BT14: =+S14*$BP14 -> 0 | BU14: =+X14*$BP14 -> 0 | BV14: =+AC14*$BP14 -> 0 | BW14: =+AH14*$BP14 -> 0 | BX14: =+AM14*$BP14 -> 0 | BY14: =+AR14*$BP14 -> 0 | BZ14: =+AW14*$BP14 -> 0 | CA14: =+BB14*$BP14 -> 0 | CB14: =+BG14*$BP14 -> 0 | CC14: =+BL14*$BP14 -> 0 | CD14: =SUM(BR14:CC14) -> 0 | CF14: OCTUBRE | CG14: =AVERAGE(AX19:BA19) -> 20.25 | CH14: =+CG$3/CG14 -> 6.0296296 | CI14: =+CA19 -> 231642.86 | CJ14: =+CI14/CG$3 -> 1897.1569
D15: BOMBERO | AN15: 2 | AO15: 2 | AP15: 3 | AQ15: 3 | AR15: 3 | AS15: 3 | AT15: 3 | AU15: 3 | AV15: 3 | AW15: 1 | AX15: 3 | AY15: 3 | AZ15: 3 | BA15: 3 | BB15: 1 | BC15: 3 | BD15: 2 | BE15: 1 | BF15: 0 | BG15: 1 | BH15: 0 | BI15: 0 | BJ15: 0 | BK15: 0 | BL15: =AVERAGE(BH15:BK15) -> 0 | BN15: BOMBERO | BO15: 2200 | BP15: =+BO15/7*30 -> 9428.5714 | BQ15: =+BP15*I15+N15*BP15+S15*BP15+X15*BP15+AC15*BP15+AH15*BP15+AM15*BP15+AR15*BP15+AW15*BP15+BB15*BP15+BG15*BP15+BL15*BP15 -> 56571.429 | BR15: =+I15*$BP15 -> 0 | BS15: =+N15*$BP15 -> 0 | BT15: =+S15*$BP15 -> 0 | BU15: =+X15*$BP15 -> 0 | BV15: =+AC15*$BP15 -> 0 | BW15: =+AH15*$BP15 -> 0 | BX15: =+AM15*$BP15 -> 0 | BY15: =+AR15*$BP15 -> 28285.714 | BZ15: =+AW15*$BP15 -> 9428.5714 | CA15: =+BB15*$BP15 -> 9428.5714 | CB15: =+BG15*$BP15 -> 9428.5714 | CC15: =+BL15*$BP15 -> 0 | CD15: =SUM(BR15:CC15) -> 56571.429 | CF15: NOVIEMBRE | CG15: =AVERAGE(BC19:BF19) -> 17.25 | CH15: =+CG$3/CG15 -> 7.0782609 | CI15: =+CB19 -> 225642.86 | CJ15: =+CI15/CG$3 -> 1848.0168
D16: ENCARGADO MTTO | AN16: 1 | AO16: 1 | AP16: 1 | AQ16: 1 | AR16: =AVERAGE(AN16:AQ16) -> 1 | AS16: 1 | AT16: 1 | AU16: 1 | AV16: 1 | AW16: =AVERAGE(AS16:AV16) -> 1 | AX16: 1 | AY16: 1 | AZ16: 1 | BA16: 1 | BB16: =AVERAGE(AX16:BA16) -> 1 | BC16: 1 | BD16: 1 | BE16: 0 | BF16: 0 | BG16: =AVERAGE(BC16:BF16) -> 0.5 | BH16: 0 | BI16: 0 | BJ16: 0 | BK16: 0 | BL16: =AVERAGE(BH16:BK16) -> 0 | BN16: ENCARGADO MTTO | BO16: 2500 | BP16: =+BO16/7*30 -> 10714.286 | BQ16: =+BP16*I16+N16*BP16+S16*BP16+X16*BP16+AC16*BP16+AH16*BP16+AM16*BP16+AR16*BP16+AW16*BP16+BB16*BP16+BG16*BP16+BL16*BP16 -> 37500 | BR16: =+I16*$BP16 -> 0 | BS16: =+N16*$BP16 -> 0 | BT16: =+S16*$BP16 -> 0 | BU16: =+X16*$BP16 -> 0 | BV16: =+AC16*$BP16 -> 0 | BW16: =+AH16*$BP16 -> 0 | BX16: =+AM16*$BP16 -> 0 | BY16: =+AR16*$BP16 -> 10714.286 | BZ16: =+AW16*$BP16 -> 10714.286 | CA16: =+BB16*$BP16 -> 10714.286 | CB16: =+BG16*$BP16 -> 5357.1429 | CC16: =+BL16*$BP16 -> 0 | CD16: =SUM(BR16:CC16) -> 37500 | CF16: DICIEMBRE | CG16: =AVERAGE(BH19:BK19) -> 6 | CH16: =+CG$3/CG16 -> 20.35 | CI16: =+CC19 -> 100285.71 | CJ16: =+CI16/CG$3 -> 821.34082 | CK16: SEGUNDO CICLO
D17: VIGILANTE | AS17: 0 | AU17: O | AV17: O | AW17: =AVERAGE(AS17:AV17) -> 0 | AX17: 0 | AY17: 3 | AZ17: 3 | BA17: 3 | BB17: =AVERAGE(AX17:BA17) -> 2.25 | BC17: 3 | BD17: 3 | BE17: 3 | BF17: 2 | BG17: =AVERAGE(BC17:BF17) -> 2.75 | BH17: 1 | BI17: 1 | BJ17: 1 | BK17: 1 | BL17: 0 | BN17: VIGILANTE | BO17: 2200 | BP17: =+BO17/7*30 -> 9428.5714 | BQ17: =+BP17*I17+N17*BP17+S17*BP17+X17*BP17+AC17*BP17+AH17*BP17+AM17*BP17+AR17*BP17+AW17*BP17+BB17*BP17+BG17*BP17+BL17*BP17 -> 47142.857 | BR17: =+I17*$BP17 -> 0 | BS17: =+N17*$BP17 -> 0 | BT17: =+S17*$BP17 -> 0 | BU17: =+X17*$BP17 -> 0 | BV17: =+AC17*$BP17 -> 0 | BW17: =+AH17*$BP17 -> 0 | BX17: =+AM17*$BP17 -> 0 | BY17: =+AR17*$BP17 -> 0 | BZ17: =+AW17*$BP17 -> 0 | CA17: =+BB17*$BP17 -> 21214.286 | CB17: =+BG17*$BP17 -> 25928.571 | CC17: =+BL17*$BP17 -> 0 | CD17: =SUM(BR17:CC17) -> 47142.857 | CF17: TOTAL | CI17: =SUM(CI5:CI16) -> 946928.57 | CJ17: COSTO TOTAL
D18: ADMINISTRADOR ALMACENISTA | AN18: 0 | AO18: 0 | AP18: 0 | AQ18: 0 | AR18: 0 | AS18: 0 | AT18: 0 | AU18: 0 | AV18: 0 | AW18: 0 | AX18: 0 | AY18: 0 | AZ18: 0 | BA18: 0 | BB18: 0 | BC18: 0 | BD18: 0 | BE18: 0 | BF18: 0 | BG18: 0 | BH18: 0 | BI18: 0 | BJ18: 0 | BK18: 0 | BL18: =AVERAGE(BH18:BK18) -> 0 | BN18: ADMINISTRADOR ALMACENISTA | BP18: =+BO18/7*30 -> 0 | BQ18: =+BP18*I18+N18*BP18+S18*BP18+X18*BP18+AC18*BP18+AH18*BP18+AM18*BP18+AR18*BP18+AW18*BP18+BB18*BP18+BG18*BP18+BL18*BP18 -> 0 | BR18: =+I18*$BP18 -> 0 | BS18: =+N18*$BP18 -> 0 | BT18: =+S18*$BP18 -> 0 | BU18: =+X18*$BP18 -> 0 | BV18: =+AC18*$BP18 -> 0 | BW18: =+AH18*$BP18 -> 0 | BX18: =+AM18*$BP18 -> 0 | BY18: =+AR18*$BP18 -> 0 | BZ18: =+AW18*$BP18 -> 0 | CA18: =+BB18*$BP18 -> 0 | CB18: =+BG18*$BP18 -> 0 | CC18: =+BL18*$BP18 -> 0 | CD18: =SUM(BR18:CC18) -> 0 | CF18: GASTO/HA | CI18: =+CI17/CG3 -> 7755.3528 | CJ18: PESOS/HA
D19: TOTAL | AN19: =SUM(AN5:AN18) -> 10 | AO19: =SUM(AO5:AO18) -> 10 | AP19: =SUM(AP5:AP18) -> 15 | AQ19: =SUM(AQ5:AQ18) -> 18 | AR19: =AVERAGE(AN19:AQ19) -> 13.25 | AS19: =SUM(AS5:AS18) -> 18 | AT19: =SUM(AT5:AT18) -> 18 | AU19: =SUM(AU5:AU18) -> 18 | AV19: =SUM(AV5:AV18) -> 18 | AW19: =AVERAGE(AS19:AV19) -> 18 | AX19: =SUM(AX5:AX18) -> 18 | AY19: =SUM(AY5:AY18) -> 21 | AZ19: =SUM(AZ5:AZ18) -> 21 | BA19: =SUM(BA5:BA18) -> 21 | BB19: =AVERAGE(AX19:BA19) -> 20.25 | BC19: =SUM(BC5:BC18) -> 21 | BD19: =SUM(BD5:BD18) -> 20 | BE19: =SUM(BE5:BE18) -> 17 | BF19: =SUM(BF5:BF18) -> 11 | BG19: =AVERAGE(BC19:BF19) -> 17.25 | BH19: =SUM(BH5:BH18) -> 6 | BI19: =SUM(BI5:BI18) -> 6 | BJ19: =SUM(BJ5:BJ18) -> 6 | BK19: =SUM(BK5:BK18) -> 6 | BL19: =AVERAGE(BH19:BK19) -> 6 | BN19: TOTAL | BO19: =SUM(BO5:BO18) -> 37500 | BP19: =SUM(BP5:BP18) -> 169285.71 | BQ19: =SUM(BQ5:BQ18) -> 946928.57 | BR19: =SUM(BR5:BR18) -> 0 | BS19: =SUM(BS5:BS18) -> 0 | BT19: =SUM(BT5:BT18) -> 0 | BU19: =SUM(BU5:BU18) -> 0 | BV19: =SUM(BV5:BV18) -> 0 | ... CD19: =SUM(CD5:CD18) -> 946928.57 | CF19: GASTO/KG | CI19: =+CI17/'PROY GPO ESCOBEDO'!R22 -> 3.8840073 | CJ19: PESO/KG
C20: =+#REF!/12 -> #REF! | D20: HAS / PERSONA | E20: =+$F2/E19 -> #DIV/0! | F20: =+$F2/F19 -> #DIV/0! | G20: =+$F2/G19 -> #DIV/0! | H20: =+$F2/H19 -> #DIV/0! | I20: =AVERAGE(E20:H20) -> #DIV/0! | J20: =+$F2/J19 -> #DIV/0! | K20: =+$F2/K19 -> #DIV/0! | L20: =+$F2/L19 -> #DIV/0! | M20: =+$F2/M19 -> #DIV/0! | N20: =AVERAGE(J20:M20) -> #DIV/0! | O20: =+$F2/O19 -> #DIV/0! | P20: =+$F2/P19 -> #DIV/0! | Q20: =+$F2/Q19 -> #DIV/0! | R20: =+$F2/R19 -> #DIV/0! | S20: =AVERAGE(O20:R20) -> #DIV/0! | T20: =+$F2/T19 -> #DIV/0! | U20: =+$F2/U19 -> #DIV/0! | V20: =+$F2/V19 -> #DIV/0! | W20: =+$F2/W19 -> #DIV/0! | X20: =AVERAGE(T20:W20) -> #DIV/0! | Y20: =+$F2/Y19 -> #DIV/0! | Z20: =+$F2/Z19 -> #DIV/0! | AA20: =+$F2/AA19 -> #DIV/0! | AB20: =+$F2/AB19 -> #DIV/0! | AC20: =AVERAGE(Y20:AB20) -> #DIV/0! | AD20: =+$F2/AD19 -> #DIV/0! | AE20: =+$F2/AE19 -> #DIV/0! | AF20: =+$F2/AF19 -> #DIV/0! | AG20: =+$F2/AG19 -> #DIV/0! | AH20: =AVERAGE(AD20:AG20) -> #DIV/0! | AI20: =+$F2/AI19 -> #DIV/0! | AJ20: =+$F2/AJ19 -> #DIV/0! | AK20: =+$F2/AK19 -> #DIV/0! | AL20: =+$F2/AL19 -> #DIV/0! | AM20: =AVERAGE(AI20:AL20) -> #DIV/0! | AN20: =+$F2/AN19 -> 33.2 | AO20: =+$F2/AO19 -> 33.2 | AP20: =+$F2/AP19 -> 22.133333 | AQ20: =+$F2/AQ19 -> 18.444444 | AR20: =AVERAGE(AN20:AQ20) -> 26.744444 | AS20: =+$F2/AS19 -> 18.444444 | AT20: =+$F2/AT19 -> 18.444444 | AU20: =+$F2/AU19 -> 18.444444 | AV20: =+$F2/AV19 -> 18.444444 | AW20: =AVERAGE(AS20:AV20) -> 18.444444 | AX20: =+$F2/AX19 -> 18.444444 | AY20: =+$F2/AY19 -> 15.809524 | AZ20: =+$F2/AZ19 -> 15.809524 | BA20: =+$F2/BA19 -> 15.809524 | BB20: =AVERAGE(AX20:BA20) -> 16.468254 | BC20: =+$F2/BC19 -> 15.809524 | BD20: =+$F2/BD19 -> 16.6 | BE20: =+$F2/BE19 -> 19.529412 | BF20: =+$F2/BF19 -> 30.181818 | BG20: =AVERAGE(BC20:BF20) -> 20.530188 | BH20: =+$F2/BH19 -> 55.333333 | BI20: =+$F2/BI19 -> 55.333333 | BJ20: =+$F2/BJ19 -> 55.333333 | BK20: =+$F2/BK19 -> 55.333333 | BL20: =AVERAGE(BH20:BK20) -> 55.333333
C21: =+#REF!/12 -> #REF! | H21: 9
C22: =+#REF!/12 -> #REF! | D22: ADMINISTRADOR DE GJAS
C23: =+#REF!/12 -> #REF! | D23: JEFE DE SEGURIDAD
D24: COMPRAS

Sheet  DIESEL 
C2: GRANJA | D2: GPO ESCOBEDO | Q2: LLENADO
C3: HAS | D3: =+'PROY GPO ESCOBEDO'!T3 -> 122.1 | Q3: DIESEL | R3: 22 | S3: LT/HR
I4: RECAMBIO DIARIO | Q4: GASTO BOMBAS | R4: 1.3 | S4: M3/SEG | U4: =+R4*3600 -> 4680 | V4: M3/HR
G5: BIOMASA | I5: DIA | J5: M3 | K5: BOMBEO HRS/DIA | M5: DIESEL | Q5: COSTO M3 EN RESERV | R5: =+(R3*R15)/(R4*3600) -> 0.11 | S5: PESOS/M3 AGUA | U5: =+R3*R15 -> 514.8 | V5: PESOS /HR
C6: FECHA | D6: EDAD | E6: pp | F6: ORG/M2 | G6: TOTAL | H6: KG/HA | I6: % REC | J6: VOLUMEN | K6: TOTAL | L6: POR BOMBA | M6: LT/SEM | N6: LTS ACUM | Q6: VOL TOTAL | R6: =+D3*10000*R7 -> 1159950 | S6: M3 | U6: =+U5/U4 -> 0.11 | V6: PESOS/ME AGUA
Q7: PROF/ PROM | R7: 0.95 | S7: MTS
Q8: HRS /DIA | R8: 16 | S8: HRS DIARIA
Q9: HRS LLENADO | R9: =(+R6*R10)/(R4*3600) -> 247.85256
Q10: % LLENADO SIEMBRA | R10: 1
Q11: NO DE BOMBAS | R11: 4
Q12: HRS POR BOMBA | R12: =+R9/R11 -> 61.963141
Q13: DIAS DE BOMBEO | R13: =+R12/R8 -> 3.8726963
Q14: HAS DIARIAS | R14: =+D3/R13 -> 31.528421
Q15: PRECIO LT DIESEL | R15: 23.4 | S15: PESOS /LT
Q17: PRIMER CICLO
Q18: HRS BOMBEADAS | R18: =+R19/R3 -> 0
Q19: LT DIESEL | R19: =+N22 -> 0
Q20: GASTO TOTAL | R20: =+R19*R15 -> 0
Q22: SEGUNDO CICLO
Q23: HRS BOMBEADAS | R23: =+R24/R3 -> 2780.9058
C24: SEGUNDO CICLO | I24: RECAMBIO DIARIO | Q24: LT DIESEL | R24: =+N41 -> 61179.927
G25: BIOMASA | I25: DIA | J25: M3 | K25: BOMBEO HRS | M25: DIESEL | Q25: GASTO TOTAL | R25: =+R24*R15 -> 1431610.3
C26: FECHA | D26: EDAD | E26: pp | F26: ORG/M2 | G26: TOTAL | H26: KG/HA | I26: % REC | J26: VOLUMEN | K26: TOTAL | L26: POR BOMBA | M26: LT/SEM | N26: LTS ACUM
C27: 45884 | D27: 0 | E27: 0.015 | F27: 17.82 | G27: =+F27*E27*10*D$3 -> 326.3733 | H27: =+G27/D$3 -> 2.673 | I27: 20 | J27: =+R$6*I27/100 -> 231990 | K27: =+J27/(R$4*3600) -> 49.570513 | L27: =+K27/R$11 -> 12.392628 | M27: =+K27*R$3*5 -> 5452.7564 | N27: =+M27 -> 5452.7564 | Q27: TOTAL PROYECTO DEL AÑO 2025
C28: =+C27+7 -> 45891 | D28: 7 | E28: 0.6 | F28: 17.424 | G28: =+F28*E28*10*D$3 -> 12764.822 | H28: =+G28/D$3 -> 104.544 | I28: 3 | J28: =+R$6*I28/100 -> 34798.5 | K28: =+J28/(R$4*3600) -> 7.4355769 | L28: =+K28/R$11 -> 1.8588942 | M28: =+K28*R$3*7 -> 1145.0788 | N28: =+N27+M28 -> 6597.8353 | Q28: LTS TOTALES | R28: =+R24+R19 -> 61179.927
C29: =+C28+7 -> 45898 | D29: 14 | E29: 1 | F29: 15.84 | G29: =+F29*E29*10*D$3 -> 19340.64 | H29: =+G29/D$3 -> 158.4 | I29: 5 | J29: =+R$6*I29/100 -> 57997.5 | K29: =+J29/(R$4*3600) -> 12.392628 | L29: =+K29/R$11 -> 3.0981571 | M29: =+K29*R$3*7 -> 1908.4647 | N29: =+N28+M29 -> 8506.3 | Q29: COSTO TOTAL | R29: =+R25+R20 -> 1431610.3
C30: =+C29+7 -> 45905 | D30: 21 | E30: 1.5 | F30: 15.444 | G30: =+F30*E30*10*D$3 -> 28285.686 | H30: =+G30/D$3 -> 231.66 | I30: 5 | J30: =+R$6*I30/100 -> 57997.5 | K30: =+J30/(R$4*3600) -> 12.392628 | L30: =+K30/R$11 -> 3.0981571 | M30: =+K30*R$3*7 -> 1908.4647 | N30: =+N29+M30 -> 10414.765
C31: =+C30+7 -> 45912 | D31: 28 | E31: 2.5 | F31: 15.048 | G31: =+F31*E31*10*D$3 -> 45934.02 | H31: =+G31/D$3 -> 376.2 | I31: 6 | J31: =+R$6*I31/100 -> 69597 | K31: =+J31/(R$4*3600) -> 14.871154 | L31: =+K31/R$11 -> 3.7177885 | M31: =+K31*R$3*7 -> 2290.1577 | N31: =+N30+M31 -> 12704.922
C32: =+C31+7 -> 45919 | D32: 35 | E32: 3.6 | F32: 14.652 | G32: =+F32*E32*10*D$3 -> 64404.331 | H32: =+G32/D$3 -> 527.472 | I32: 6 | J32: =+R$6*I32/100 -> 69597 | K32: =+J32/(R$4*3600) -> 14.871154 | L32: =+K32/R$11 -> 3.7177885 | M32: =+K32*R$3*7 -> 2290.1577 | N32: =+N31+M32 -> 14995.08
C33: =+C32+7 -> 45926 | D33: 42 | E33: 5 | F33: 14.256 | G33: =+F33*E33*10*D$3 -> 87032.88 | H33: =+G33/D$3 -> 712.8 | I33: 6 | J33: =+R$6*I33/100 -> 69597 | K33: =+J33/(R$4*3600) -> 14.871154 | L33: =+K33/R$11 -> 3.7177885 | M33: =+K33*R$3*7 -> 2290.1577 | N33: =+N32+M33 -> 17285.238
C34: =+C33+7 -> 45933 | D34: 49 | E34: 6.4 | F34: 13.86 | G34: =+F34*E34*10*D$3 -> 108307.58 | H34: =+G34/D$3 -> 887.04 | I34: 7 | J34: =+R$6*I34/100 -> 81196.5 | K34: =+J34/(R$4*3600) -> 17.349679 | L34: =+K34/R$11 -> 4.3374199 | M34: =+K34*R$3*7 -> 2671.8506 | N34: =+N33+M34 -> 19957.088
C35: =+C34+7 -> 45940 | D35: 56 | E35: 7.8 | F35: 13.464 | G35: =+F35*E35*10*D$3 -> 128228.44 | H35: =+G35/D$3 -> 1050.192 | I35: 8 | J35: =+R$6*I35/100 -> 92796 | K35: =+J35/(R$4*3600) -> 19.828205 | L35: =+K35/R$11 -> 4.9570513 | M35: =+K35*R$3*7 -> 3053.5436 | N35: =+N34+M35 -> 23010.632
C36: =+C35+7 -> 45947 | D36: 63 | E36: 9.2 | F36: 13.068 | G36: =+F36*E36*10*D$3 -> 146795.46 | H36: =+G36/D$3 -> 1202.256 | I36: 10 | J36: =+R$6*I36/100 -> 115995 | K36: =+J36/(R$4*3600) -> 24.785256 | L36: =+K36/R$11 -> 6.1963141 | M36: =+K36*R$3*7 -> 3816.9295 | N36: =+N35+M36 -> 26827.562
C37: =+C36+7 -> 45954 | D37: 70 | E37: 10.6 | F37: 12.672 | G37: =+F37*E37*10*D$3 -> 164008.63 | H37: =+G37/D$3 -> 1343.232 | I37: 15 | J37: =+R$6*I37/100 -> 173992.5 | K37: =+J37/(R$4*3600) -> 37.177885 | L37: =+K37/R$11 -> 9.2944712 | M37: =+K37*R$3*7 -> 5725.3942 | N37: =+N36+M37 -> 32552.956
C38: =+C37+7 -> 45961 | D38: 77 | E38: 12 | F38: 12.276 | G38: =+F38*E38*10*D$3 -> 179867.95 | H38: =+G38/D$3 -> 1473.12 | I38: 19 | J38: =+R$6*I38/100 -> 220390.5 | K38: =+J38/(R$4*3600) -> 47.091987 | L38: =+K38/R$11 -> 11.772997 | M38: =+K38*R$3*7 -> 7252.166 | N38: =+N37+M38 -> 39805.122
C39: =+C38+7 -> 45968 | D39: =+D38+7 -> 84 | E39: 13.4 | F39: 10.177 | G39: =+F39*E39*10*D$3 -> 166509.97 | H39: =+G39/D$3 -> 1363.718 | I39: 18 | J39: =+R$6*I39/100 -> 208791 | K39: =+J39/(R$4*3600) -> 44.613462 | L39: =+K39/R$11 -> 11.153365 | M39: =+K39*R$3*7 -> 6870.4731 | N39: =+N38+M39 -> 46675.595
C40: =+C39+7 -> 45975 | D40: =+D39+7 -> 91 | E40: 14.8 | F40: 10.078 | G40: =+F40*E40*10*D$3 -> 182117.52 | H40: =+G40/D$3 -> 1491.544 | I40: 19 | J40: =+R$6*I40/100 -> 220390.5 | K40: =+J40/(R$4*3600) -> 47.091987 | L40: =+K40/R$11 -> 11.772997 | M40: =+K40*R$3*7 -> 7252.166 | N40: =+N39+M40 -> 53927.761
C41: =+C40+7 -> 45982 | D41: =+D40+7 -> 98 | E41: 16.2 | F41: 10.078 | G41: =+F41*E41*10*D$3 -> 199344.86 | H41: =+G41/D$3 -> 1632.636 | I41: 19 | J41: =+R$6*I41/100 -> 220390.5 | K41: =+J41/(R$4*3600) -> 47.091987 | L41: =+K41/R$11 -> 11.772997 | M41: =+K41*R$3*7 -> 7252.166 | N41: =+N40+M41 -> 61179.927
F43: GPO ESCOBEDO
F44: FECHA | G44: LTS/MES | H44: $ / MES
...

Sheet PROY GPO ESCOBEDO
N1: 36
R2: DENSIDAD | T2: HAS
F3: GRUPO ESCOBEDO SEGUNDO CICLO | R3: 18 | S3: ORG/M2 | T3: 122.1
F5: % MORT | G5: 1.6 | I5: BIOMASA | K5: ALIMENTO | Q5: PRECOSECHA | T5: PREC. ACUM
B6: TIPO DE ALIMENTO | C6: FECHA | D6: EDAD | E6: pp | F6: inc | G6: % SOB | H6: ORG/M2 | I6: TOTAL | J6: KG/HA | K6: KHD | L6: % BW | M6: KILOS/SEM | N6: ACUM | O6: FCA | P6: PP | Q6: ORG/M2 | R6: KG TOT | S6: KG/HA | T6: ORG/M TOT | U6: KG TOTALES | V6: INGRESO
B7: APICAMARON RACEWAYS 3 | C7: 45886 | D7: 0 | E7: 0.015 | G7: 100 | H7: 18 | I7: 329.67 | J7: 2.7 | K7: 0.54 | L7: 0.2 | M7: 461.538 | N7: 374
B8: APICAMARON RACEWAYS 3 | C8: 45893 | D8: 7 | E8: 0.6 | F8: 0.585 | G8: 98.4 | H8: 17.712 | I8: 12975.811 | J8: 106.272 | K8: 10.6272 | L8: 0.1 | M8: 9083.0678 | N8: 9544.6058 | O8: 0.73556911
B9: APICAMARON RACEWAYS 3 | C9: 45900 | D9: 14 | E9: 1 | F9: 0.4 | G9: 96.8 | H9: 17.424 | I9: 21274.704 | J9: 174.24 | K9: 13.9392 | L9: 0.08 | M9: 11913.834 | N9: 21458.44 | O9: 1.0086364
B10: APICAMARON RACEWAYS 4 | C10: 45907 | D10: 21 | E10: 1.5 | F10: 0.5 | G10: 95.2 | H10: 17.136 | I10: 31384.584 | J10: 257.04 | K10: 14.90832 | L10: 0.058 | M10: 12742.141 | N10: 34200.581 | O10: 1.0897255
B11: APICAMARON RACEWAYS 4 | C11: 45914 | D11: 28 | E11: 2.5 | F11: 1 | G11: 93.6 | H11: 16.848 | I11: 51428.52 | J11: 421.2 | K11: 16.848 | L11: 0.04 | M11: 14399.986 | N11: 48600.567 | O11: 0.94501197
B12: DINAMO 35´30 (1.8 mm) | C12: 45921 | D12: 35 | E12: 3.6 | F12: 1.1 | G12: 92 | H12: 16.56 | I12: 72791.136 | J12: 596.16 | K12: 23.8464 | L12: 0.04 | M12: 20381.518 | N12: 68982.085 | O12: 0.9476715
B13: DINAMO 35´15 (1.8 mm) | C13: 45928 | D13: 42 | E13: 4.9 | F13: 1.3 | G13: 90.4 | H13: 16.272 | I13: 97353.749 | J13: 797.328 | K13: 30.298464 | L13: 0.038 | M13: 25896.097 | N13: 94878.182 | O13: 0.97457143
B14: DINAMO 35´15 (1.8 mm) | C14: 45935 | D14: 49 | E14: 6.2 | F14: 1.3 | G14: 88.8 | H14: 15.984 | I14: 121002.08 | J14: 991.008 | K14: 37.658304 | L14: 0.038 | M14: 32186.552 | N14: 127064.73 | O14: 1.0501037
B15: DINAMO 35´15 (1.8 mm) | C15: 45942 | D15: 56 | E15: 7.5 | F15: 1.3 | G15: 87.2 | H15: 15.696 | I15: 143736.12 | J15: 1177.2 | K15: 44.7336 | L15: 0.038 | M15: 38233.808 | N15: 165298.54 | O15: 1.1500139
B16: DINAMO 35´15 (1.8 mm) | C16: 45949 | D16: 63 | E16: 8.8 | F16: 1.3 | G16: 85.6 | H16: 15.408 | I16: 165555.88 | J16: 1355.904 | K16: 51.524352 | L16: 0.038 | M16: 44037.864 | N16: 209336.41 | O16: 1.2644456 | R16: 0 | S16: 0 | T16: 0 | U16: 0
B17: DINAMO 35´15 (1.8 mm) | C17: 45956 | D17: 70 | E17: 10.1 | F17: 1.3 | G17: 84 | H17: 12.62 | I17: 155631.1 | J17: 1274.62 | K17: 48.43556 | L17: 0.038 | M17: 41397.873 | N17: 250734.28 | O17: 1.3446984 | P17: 10.1 | Q17: 2.5 | R17: 30830.25 | S17: 252.5 | T17: 2.5 | U17: 30830.25 | V17: 1914558.5
B18: DINAMO 35´15 (1.8 mm) | C18: 45963 | D18: 77 | E18: 11.4 | F18: 1.3 | G18: 82.4 | H18: 12.332 | I18: 171654.04 | J18: 1405.848 | K18: 49.20468 | L18: 0.035 | M18: 42055.24 | N18: 292789.52 | O18: 1.4459863 | T18: 2.5 | U18: 30830.25
B19: DINAMO 35´15 (1.8 mm) | C19: 45970 | D19: 84 | E19: 12.8 | F19: 1.4 | G19: 80.8 | H19: 10.044 | I19: 156975.67 | J19: 1285.632 | K19: 44.99712 | L19: 0.035 | M19: 38459.038 | N19: 331248.56 | O19: 1.5121119 | P19: 12.8 | Q19: 2 | R19: 31257.6 | S19: 256 | T19: 4.5 | U19: 62087.85 | V19: 2119265.3
B20: DINAMO 35´15 (1.8 mm) | C20: 45977 | D20: 91 | E20: 14.2 | F20: 1.4 | G20: 78 | H20: 9.54 | I20: 165406.43 | J20: 1354.68 | K20: 47.4138 | L20: 0.035 | M20: 40524.575 | N20: 371773.13 | O20: 1.6342087 | T20: 4.5 | U20: 62087.85
B21: DINAMO 35´15 (1.8 mm) | C21: 45984 | D21: 98 | E21: 15.6 | F21: 1.4 | G21: 78 | H21: 0 | I21: 0 | J21: 0 | K21: 47.4138 | L21: 0.035 | M21: 40524.575 | N21: 412297.71 | O21: 1.6911173 | P21: 15.6 | Q21: 9.54 | R21: 181714.1 | S21: 1488.24 | T21: 14.04 | U21: 243801.95 | V21: 13737586
Q22: 14.04 | R22: 243801.95 | S22: 1996.74 | V22: 17771410
U23: POR HA
N24: PRODUCCIÓN 2DO CICLO | S24: ALIM TOTAL | T24: 412297.71 | U24: =+T24/T3 -> 3376.7216
O25: PP (GR) | P25: KG | S25: FCA | T25: 1.6911173
N26: 1R PRECOSECHA | O26: 10.1 | P26: 30830.25 | S26: $/KG ALIM | T26: 21
N27: 2DA PRECOSECHA | O27: 12.8 | P27: 31257.6 | S27: PRECIO MILLAR PL | T27: 4.6
N28: COSECHA FINAL | O28: 15.6 | P28: 181714.1 | S28: COSTO ALIM | T28: 8658251.9 | U28: 70911.154
N29: TOTAL | P29: 243801.95 | S29: COSTO LARVA | T29: 2021976 | U29: 16560
N30: POR HA | P30: 1996.74 | S30: INGRESO TOT | T30: 17771410 | U30: 145547.99
S31: VALOR DLS | T31: 20

Sheet MEMORIA DE CALCULO
D2: MEMORIA DE CALCULO 2025 GPO ESCOBEDO
D4: DATOS TECNICOS PRIMER CICLO DESEMBOCADEROS 2025 | J4: DATOS TECNICOS SEGUNDO CICLO GPO ESCOBEDO 2025 | O4: PROYECTO DE COSTOS DIRECTOS DE PRODUCCION 2025
D5: HAS | E5: =+'PROY GPO ESCOBEDO'!T3 -> 122.1 | J5: HAS | K5: =+E5 -> 122.1 | O5: CONCEPTO | P5: COSTO TOTAL | Q5: COSTO/HA | R5: % DEL COSTO | S5: $/KG
D6: DENSIDAD SIEMBRA | E6: =+'PROY GPO ESCOBEDO'!#REF! -> #REF! | F6: ORG/M2 | J6: DENSIDAD SIEMBRA | K6: =+'PROY GPO ESCOBEDO'!R3 -> 18 | L6: ORG/M2 | O6: ALIMENTO | P6: =+K24*K20 -> 8658251.9 | Q6: =+P6/K$5 -> 70911.154 | R6: =+P6/P$12 -> 0.57662991 | S6: =+P6/K$13 -> 35.513464
D7: PP PRIMER PREC | E7: ='PROY GPO ESCOBEDO'!F25 -> 0 | F7: GR | J7: PP PRIMER PREC | K7: =+'PROY GPO ESCOBEDO'!P17 -> 10.1 | L7: GR | O7: LARVA | P7: =+K6*10*K5*K21*K25 -> 2021976 | Q7: =+P7/K$5 -> 16560 | R7: =+P7/P$12 -> 0.13466134 | S7: =+P7/K$13 -> 8.2935184
D8: PP SEGUNDA PREC | E8: ='PROY GPO ESCOBEDO'!F26 -> 0 | F8: GR | J8: PP SEGUNDA PREC | K8: =+'PROY GPO ESCOBEDO'!P19 -> 12.8 | L8: GR | O8: NOMINA | P8: =SUM('INGRESO PERSONAL'!CI11:CI16) -> 946928.57 | Q8: =+P8/K$5 -> 7755.3528 | R8: =+P8/P$12 -> 0.063064386 | S8: =+P8/K$13 -> 3.8840073
D9: COSECHA FINAL | E9: ='PROY GPO ESCOBEDO'!F27 -> 0 | F9: GR | J9: COSECHA FINAL | K9: =+'PROY GPO ESCOBEDO'!P21 -> 15.6 | L9: GR | O9: DIESEL | P9: =+' DIESEL '!N41*' DIESEL '!R15+' DIESEL '!H61 -> 1431610.3 | Q9: =+P9/K$5 -> 11724.9 | R9: =+P9/P$12 -> 0.095343647 | S9: =+P9/K$13 -> 5.8720214
D10: KG PRIMER PREC | E10: ='PROY GPO ESCOBEDO'!G25 -> 0 | F10: KG TOTALES | J10: KG PRIMER PREC | K10: =+'PROY GPO ESCOBEDO'!R17 -> 30830.25 | L10: KG TOTALES | O10: GASOLINA | P10: 256500 | Q10: =+P10/K$5 -> 2100.7371 | R10: =+P10/P$12 -> 0.017082614 | S10: =+P10/K$13 -> 1.0520834
D11: KG SEG PREC | E11: ='PROY GPO ESCOBEDO'!G26 -> 0 | F11: KG TOTALES | J11: KG SEG PREC | K11: =+'PROY GPO ESCOBEDO'!R19 -> 31257.6 | L11: KG TOTALES | O11: VARIOS | P11: 1700000 | Q11: =+P11/K$5 -> 13923.014 | R11: =+P11/P$12 -> 0.1132181 | S11: =+P11/K$13 -> 6.9728727
D12: KG FINAL | E12: ='PROY GPO ESCOBEDO'!G27 -> 0 | F12: KG TOTALES | J12: KG FINAL | K12: =+'PROY GPO ESCOBEDO'!R21 -> 181714.1 | L12: KG TOTALES | O12: COSTO TOTAL | P12: =SUM(P6:P11) -> 15015267 | Q12: =+P12/K$5 -> 122975.16 | R12: =+P12/P$12 -> 1 | S12: =+P12/K$13 -> 61.587967
D13: PROD TOTAL KG BIOMASA | E13: =SUM(E10:E12) -> 0 | F13: KG TOTALES | J13: PROD TOTAL KG BIOMASA | K13: =SUM(K10:K12) -> 243801.95 | L13: KG TOTALES
D14: KG /HA 1R PREC | E14: =+E10/E$5 -> 0 | F14: KG/HA | J14: KG /HA 1R PREC | K14: =+K10/K$5 -> 252.5 | L14: KG/HA | O14: PROYECTO DE INGRESOS GPO ESCOBEDO 2025
D15: KG /HA 2DA PREC | E15: =+E11/E$5 -> 0 | F15: KG/HA | J15: KG /HA 2DA PREC | K15: =+K11/K$5 -> 256 | L15: KG/HA | P15: INGRESO TOTAL | Q15: $/HA | R15: $/KG
D16: KG /HA FINAL | E16: =+E12/E$5 -> 0 | F16: KG/HA | J16: KG /HA FINAL | K16: =+K12/K$5 -> 1488.24 | L16: KG/HA | O16: PRECOSECHA 1 | P16: =+'PROY GPO ESCOBEDO'!V17 -> 1914558.5 | Q16: =+P16/K$5 -> 15680.25 | R16: =+P16/K10 -> 62.1
D17: PROD TOTAL/HA | E17: =+E13/E$5 -> 0 | F17: KG/HA | J17: PROD TOTAL/HA | K17: =+K13/K$5 -> 1996.74 | L17: KG/HA | O17: PRECOSECHA 2 | P17: =+'PROY GPO ESCOBEDO'!V19 -> 2119265.3 | Q17: =+P17/K$5 -> 17356.8 | R17: =+P17/K11 -> 67.8
D18: % SOB | E18: =+'PROY GPO ESCOBEDO'!G21 -> 78 | F18: % SOB | J18: % SOB | K18: =+'PROY GPO ESCOBEDO'!G21 -> 78 | L18: % SOB | O18: COSECHA FINAL | P18: =+'PROY GPO ESCOBEDO'!V21 -> 13737586 | Q18: =+P18/K$5 -> 112510.94 | R18: =+P18/K12 -> 75.6
D19: FCA | E19: =+'PROY GPO ESCOBEDO'!O21 -> 1.6911173 | J19: FCA | K19: =+'PROY GPO ESCOBEDO'!O21 -> 1.6911173 | P19: =SUM(P16:P18) -> 17771410 | Q19: =+P19/K$5 -> 145547.99 | R19: =+P19/K13 -> 72.892812
D20: KG TOTALES ALIMENTO | E20: =+E19*E13 -> 0 | F20: KG TOT | J20: KG TOTALES ALIMENTO | K20: =+K19*K13 -> 412297.71 | L20: KG TOT
D21: PRECIO DLS | E21: 20 | J21: PRECIO DLS | K21: 20 | O21: UTILIDAD SEGUNDO CICLO
P22: TOTAL | Q22: POR HA
D23: COSTOS | E23: PRECIO UNITARIO | J23: COSTOS | K23: PRECIO UNITARIO | O23: COSTO TOTAL | P23: =+P12 -> 15015267 | Q23: =+P23/K$5 -> 122975.16
D24: ALIMENTO | E24: 20.14 | J24: ALIMENTO | K24: =+'PROY GPO ESCOBEDO'!T26 -> 21 | O24: INGRESO POR VENTAS | P24: =+P19 -> 17771410 | Q24: =+P24/K$5 -> 145547.99
D25: LARVA | E25: 4.6 | J25: LARVA | K25: =+'PROY GPO ESCOBEDO'!T27 -> 4.6 | O25: UTILIDAD | P25: =+P24-P23 -> 2756143.4 | Q25: =+P25/K$5 -> 22572.837
O26: $ UTILIDAD POR KG | P26: =+P25/K13 -> 11.304845
D27: PROYECTO DE COSTOS DIRECTOS DE PRODUCCION 2025 | O27: TIR (POR CICLO) | P27: =+P24/P23 -> 1.1835561
D28: CONCEPTO | E28: COSTO TOTAL | F28: COSTO/HA | G28: % DEL COSTO | H28: $/KG
D29: ALIMENTO
D30: LARVA
D31: NOMINA
D32: DIESEL
D33: GASOLINA
D34: VARIOS
D35: COSTO TOTAL
D37: PROYECTO DE INGRESOS TOPO 2025
E38: INGRESO TOTAL | F38: $/HA | G38: $/KG
D39: PRECOSECHA 1 | E39: =+'PROY GPO ESCOBEDO'!#REF! -> #REF! | F39: =+E39/E$5 -> #REF! | G39: =+E39/E10 -> #REF! | U39: =1400*K5 -> 170940
D40: PRECOSECHA 2 | E40: =+'PROY GPO ESCOBEDO'!#REF! -> #REF! | F40: =+E40/E$5 -> #REF! | G40: =+E40/E11 -> #REF! | U40: =+U37/U39 -> 0
D41: COSECHA FINAL | E41: =+'PROY GPO ESCOBEDO'!#REF! -> #REF! | F41: =+E41/E$5 -> #REF! | G41: =+E41/E12 -> #REF!
E42: =SUM(E39:E41) -> #REF! | F42: =+E42/E$5 -> #REF! | G42: =+E42/E13 -> #REF!
D44: UTILIDAD PRIMER CICLO
...
